[2023-12-23T05:22:14.729+0000] {taskinstance.py:1103} INFO - Dependencies all met for dep_context=non-requeueable deps ti=<TaskInstance: producer_dag.generate_random_data_task manual__2023-12-23T05:22:13.452816+00:00 [queued]>
[2023-12-23T05:22:14.736+0000] {taskinstance.py:1103} INFO - Dependencies all met for dep_context=requeueable deps ti=<TaskInstance: producer_dag.generate_random_data_task manual__2023-12-23T05:22:13.452816+00:00 [queued]>
[2023-12-23T05:22:14.736+0000] {taskinstance.py:1308} INFO - Starting attempt 1 of 1
[2023-12-23T05:22:14.749+0000] {taskinstance.py:1327} INFO - Executing <Task(PythonOperator): generate_random_data_task> on 2023-12-23 05:22:13.452816+00:00
[2023-12-23T05:22:14.755+0000] {standard_task_runner.py:57} INFO - Started process 464 to run task
[2023-12-23T05:22:14.757+0000] {standard_task_runner.py:84} INFO - Running: ['***', 'tasks', 'run', 'producer_dag', 'generate_random_data_task', 'manual__2023-12-23T05:22:13.452816+00:00', '--job-id', '13', '--raw', '--subdir', 'DAGS_FOLDER/producer.py', '--cfg-path', '/tmp/tmp_cxbhk5w']
[2023-12-23T05:22:14.761+0000] {standard_task_runner.py:85} INFO - Job 13: Subtask generate_random_data_task
[2023-12-23T05:22:14.805+0000] {task_command.py:410} INFO - Running <TaskInstance: producer_dag.generate_random_data_task manual__2023-12-23T05:22:13.452816+00:00 [running]> on host 0a80305749dd
[2023-12-23T05:22:14.873+0000] {taskinstance.py:1547} INFO - Exporting env vars: AIRFLOW_CTX_DAG_OWNER='***' AIRFLOW_CTX_DAG_ID='producer_dag' AIRFLOW_CTX_TASK_ID='generate_random_data_task' AIRFLOW_CTX_EXECUTION_DATE='2023-12-23T05:22:13.452816+00:00' AIRFLOW_CTX_TRY_NUMBER='1' AIRFLOW_CTX_DAG_RUN_ID='manual__2023-12-23T05:22:13.452816+00:00'
[2023-12-23T05:22:35.915+0000] {taskinstance.py:1824} ERROR - Task failed with exception
Traceback (most recent call last):
  File "/home/airflow/.local/lib/python3.7/site-packages/airflow/operators/python.py", line 181, in execute
    return_value = self.execute_callable()
  File "/home/airflow/.local/lib/python3.7/site-packages/airflow/operators/python.py", line 198, in execute_callable
    return self.python_callable(*self.op_args, **self.op_kwargs)
  File "/opt/airflow/dags/producer.py", line 21, in generate_random_data
    password="airflow"
  File "/home/airflow/.local/lib/python3.7/site-packages/psycopg2/__init__.py", line 122, in connect
    conn = _connect(dsn, connection_factory=connection_factory, **kwasync)
psycopg2.OperationalError: connection to server at "192.168.35.133", port 5432 failed: Connection refused
	Is the server running on that host and accepting TCP/IP connections?

[2023-12-23T05:22:35.923+0000] {taskinstance.py:1350} INFO - Marking task as FAILED. dag_id=producer_dag, task_id=generate_random_data_task, execution_date=20231223T052213, start_date=20231223T052214, end_date=20231223T052235
[2023-12-23T05:22:35.937+0000] {standard_task_runner.py:109} ERROR - Failed to execute job 13 for task generate_random_data_task (connection to server at "192.168.35.133", port 5432 failed: Connection refused
	Is the server running on that host and accepting TCP/IP connections?
; 464)
[2023-12-23T05:22:35.967+0000] {local_task_job_runner.py:225} INFO - Task exited with return code 1
[2023-12-23T05:22:35.981+0000] {taskinstance.py:2653} INFO - 0 downstream tasks scheduled from follow-on schedule check
