[2024-01-09T06:10:50.771+0000] {taskinstance.py:1103} INFO - Dependencies all met for dep_context=non-requeueable deps ti=<TaskInstance: retrain_dag.train_and_save_model scheduled__2024-01-09T06:06:00+00:00 [queued]>
[2024-01-09T06:10:50.782+0000] {taskinstance.py:1103} INFO - Dependencies all met for dep_context=requeueable deps ti=<TaskInstance: retrain_dag.train_and_save_model scheduled__2024-01-09T06:06:00+00:00 [queued]>
[2024-01-09T06:10:50.782+0000] {taskinstance.py:1308} INFO - Starting attempt 1 of 1
[2024-01-09T06:10:50.800+0000] {taskinstance.py:1327} INFO - Executing <Task(PythonOperator): train_and_save_model> on 2024-01-09 06:06:00+00:00
[2024-01-09T06:10:50.810+0000] {standard_task_runner.py:57} INFO - Started process 107 to run task
[2024-01-09T06:10:50.814+0000] {standard_task_runner.py:84} INFO - Running: ['***', 'tasks', 'run', 'retrain_dag', 'train_and_save_model', 'scheduled__2024-01-09T06:06:00+00:00', '--job-id', '298', '--raw', '--subdir', 'DAGS_FOLDER/retrain_dag.py', '--cfg-path', '/tmp/tmpyxabt3_1']
[2024-01-09T06:10:50.815+0000] {standard_task_runner.py:85} INFO - Job 298: Subtask train_and_save_model
[2024-01-09T06:10:50.873+0000] {task_command.py:410} INFO - Running <TaskInstance: retrain_dag.train_and_save_model scheduled__2024-01-09T06:06:00+00:00 [running]> on host 93456042b127
[2024-01-09T06:10:50.966+0000] {taskinstance.py:1547} INFO - Exporting env vars: AIRFLOW_CTX_DAG_OWNER='***' AIRFLOW_CTX_DAG_ID='retrain_dag' AIRFLOW_CTX_TASK_ID='train_and_save_model' AIRFLOW_CTX_EXECUTION_DATE='2024-01-09T06:06:00+00:00' AIRFLOW_CTX_TRY_NUMBER='1' AIRFLOW_CTX_DAG_RUN_ID='scheduled__2024-01-09T06:06:00+00:00'
[2024-01-09T06:11:11.986+0000] {taskinstance.py:1824} ERROR - Task failed with exception
Traceback (most recent call last):
  File "/home/airflow/.local/lib/python3.7/site-packages/airflow/operators/python.py", line 181, in execute
    return_value = self.execute_callable()
  File "/home/airflow/.local/lib/python3.7/site-packages/airflow/operators/python.py", line 198, in execute_callable
    return self.python_callable(*self.op_args, **self.op_kwargs)
  File "/opt/airflow/dags/retrain_dag.py", line 25, in train_and_save_model
    password="airflow"
  File "/home/airflow/.local/lib/python3.7/site-packages/psycopg2/__init__.py", line 122, in connect
    conn = _connect(dsn, connection_factory=connection_factory, **kwasync)
psycopg2.OperationalError: connection to server at "192.168.35.140", port 5432 failed: Connection refused
	Is the server running on that host and accepting TCP/IP connections?

[2024-01-09T06:11:11.994+0000] {taskinstance.py:1350} INFO - Marking task as FAILED. dag_id=retrain_dag, task_id=train_and_save_model, execution_date=20240109T060600, start_date=20240109T061050, end_date=20240109T061111
[2024-01-09T06:11:12.007+0000] {standard_task_runner.py:109} ERROR - Failed to execute job 298 for task train_and_save_model (connection to server at "192.168.35.140", port 5432 failed: Connection refused
	Is the server running on that host and accepting TCP/IP connections?
; 107)
[2024-01-09T06:11:12.045+0000] {local_task_job_runner.py:225} INFO - Task exited with return code 1
[2024-01-09T06:11:12.060+0000] {taskinstance.py:2653} INFO - 0 downstream tasks scheduled from follow-on schedule check
