[2023-10-20T14:21:44.264+0000] {taskinstance.py:1103} INFO - Dependencies all met for dep_context=non-requeueable deps ti=<TaskInstance: retrain_dag.train_and_save_model manual__2023-10-20T14:21:41.870150+00:00 [queued]>
[2023-10-20T14:21:44.273+0000] {taskinstance.py:1103} INFO - Dependencies all met for dep_context=requeueable deps ti=<TaskInstance: retrain_dag.train_and_save_model manual__2023-10-20T14:21:41.870150+00:00 [queued]>
[2023-10-20T14:21:44.273+0000] {taskinstance.py:1308} INFO - Starting attempt 1 of 1
[2023-10-20T14:21:44.299+0000] {taskinstance.py:1327} INFO - Executing <Task(PythonOperator): train_and_save_model> on 2023-10-20 14:21:41.870150+00:00
[2023-10-20T14:21:44.304+0000] {standard_task_runner.py:57} INFO - Started process 534 to run task
[2023-10-20T14:21:44.306+0000] {standard_task_runner.py:84} INFO - Running: ['***', 'tasks', 'run', 'retrain_dag', 'train_and_save_model', 'manual__2023-10-20T14:21:41.870150+00:00', '--job-id', '115', '--raw', '--subdir', 'DAGS_FOLDER/retrain_dag.py', '--cfg-path', '/tmp/tmpix9leg7d']
[2023-10-20T14:21:44.307+0000] {standard_task_runner.py:85} INFO - Job 115: Subtask train_and_save_model
[2023-10-20T14:21:44.342+0000] {task_command.py:410} INFO - Running <TaskInstance: retrain_dag.train_and_save_model manual__2023-10-20T14:21:41.870150+00:00 [running]> on host bea49855d648
[2023-10-20T14:21:44.402+0000] {taskinstance.py:1547} INFO - Exporting env vars: AIRFLOW_CTX_DAG_OWNER='***' AIRFLOW_CTX_DAG_ID='retrain_dag' AIRFLOW_CTX_TASK_ID='train_and_save_model' AIRFLOW_CTX_EXECUTION_DATE='2023-10-20T14:21:41.870150+00:00' AIRFLOW_CTX_TRY_NUMBER='1' AIRFLOW_CTX_DAG_RUN_ID='manual__2023-10-20T14:21:41.870150+00:00'
[2023-10-20T14:21:50.895+0000] {taskinstance.py:1824} ERROR - Task failed with exception
Traceback (most recent call last):
  File "/home/airflow/.local/lib/python3.7/site-packages/airflow/operators/python.py", line 181, in execute
    return_value = self.execute_callable()
  File "/home/airflow/.local/lib/python3.7/site-packages/airflow/operators/python.py", line 198, in execute_callable
    return self.python_callable(*self.op_args, **self.op_kwargs)
  File "/opt/airflow/dags/retrain_dag.py", line 61, in train_and_save_model
    dump(best_model, f'/home/user/airflow2/models/reg_clust_{int(cluster)}.pkl')
  File "/home/airflow/.local/lib/python3.7/site-packages/joblib/numpy_pickle.py", line 552, in dump
    with open(filename, 'wb') as f:
FileNotFoundError: [Errno 2] No such file or directory: '/home/user/airflow2/models/reg_clust_0.pkl'
[2023-10-20T14:21:50.901+0000] {taskinstance.py:1350} INFO - Marking task as FAILED. dag_id=retrain_dag, task_id=train_and_save_model, execution_date=20231020T142141, start_date=20231020T142144, end_date=20231020T142150
[2023-10-20T14:21:50.909+0000] {standard_task_runner.py:109} ERROR - Failed to execute job 115 for task train_and_save_model ([Errno 2] No such file or directory: '/home/user/airflow2/models/reg_clust_0.pkl'; 534)
[2023-10-20T14:21:50.937+0000] {local_task_job_runner.py:225} INFO - Task exited with return code 1
[2023-10-20T14:21:50.947+0000] {taskinstance.py:2653} INFO - 0 downstream tasks scheduled from follow-on schedule check
