[2023-12-24T00:51:13.389+0000] {taskinstance.py:1103} INFO - Dependencies all met for dep_context=non-requeueable deps ti=<TaskInstance: consumer_dag.consume_task manual__2023-12-24T00:51:12.517843+00:00 [queued]>
[2023-12-24T00:51:13.396+0000] {taskinstance.py:1103} INFO - Dependencies all met for dep_context=requeueable deps ti=<TaskInstance: consumer_dag.consume_task manual__2023-12-24T00:51:12.517843+00:00 [queued]>
[2023-12-24T00:51:13.396+0000] {taskinstance.py:1308} INFO - Starting attempt 1 of 1
[2023-12-24T00:51:13.407+0000] {taskinstance.py:1327} INFO - Executing <Task(PythonOperator): consume_task> on 2023-12-24 00:51:12.517843+00:00
[2023-12-24T00:51:13.411+0000] {standard_task_runner.py:57} INFO - Started process 617 to run task
[2023-12-24T00:51:13.413+0000] {standard_task_runner.py:84} INFO - Running: ['***', 'tasks', 'run', 'consumer_dag', 'consume_task', 'manual__2023-12-24T00:51:12.517843+00:00', '--job-id', '32', '--raw', '--subdir', 'DAGS_FOLDER/consumer.py', '--cfg-path', '/tmp/tmpgeky2tyz']
[2023-12-24T00:51:13.414+0000] {standard_task_runner.py:85} INFO - Job 32: Subtask consume_task
[2023-12-24T00:51:13.450+0000] {task_command.py:410} INFO - Running <TaskInstance: consumer_dag.consume_task manual__2023-12-24T00:51:12.517843+00:00 [running]> on host 6206428d3fd4
[2023-12-24T00:51:13.524+0000] {taskinstance.py:1547} INFO - Exporting env vars: AIRFLOW_CTX_DAG_OWNER='***' AIRFLOW_CTX_DAG_ID='consumer_dag' AIRFLOW_CTX_TASK_ID='consume_task' AIRFLOW_CTX_EXECUTION_DATE='2023-12-24T00:51:12.517843+00:00' AIRFLOW_CTX_TRY_NUMBER='1' AIRFLOW_CTX_DAG_RUN_ID='manual__2023-12-24T00:51:12.517843+00:00'
[2023-12-24T00:51:13.527+0000] {logging_mixin.py:150} INFO - 상혁4
[2023-12-24T00:51:13.539+0000] {logging_mixin.py:150} INFO - 타입입니당 <class 'cimpl.Message'>
[2023-12-24T00:51:13.540+0000] {taskinstance.py:1824} ERROR - Task failed with exception
Traceback (most recent call last):
  File "/home/airflow/.local/lib/python3.7/site-packages/airflow/operators/python.py", line 181, in execute
    return_value = self.execute_callable()
  File "/home/airflow/.local/lib/python3.7/site-packages/airflow/operators/python.py", line 198, in execute_callable
    return self.python_callable(*self.op_args, **self.op_kwargs)
  File "/opt/airflow/dags/consumer.py", line 49, in consume
    if msg.error().code() != KafkaException._PARTITION_EOF:
AttributeError: type object 'KafkaException' has no attribute '_PARTITION_EOF'
[2023-12-24T00:51:13.547+0000] {taskinstance.py:1350} INFO - Marking task as FAILED. dag_id=consumer_dag, task_id=consume_task, execution_date=20231224T005112, start_date=20231224T005113, end_date=20231224T005113
[2023-12-24T00:51:13.556+0000] {standard_task_runner.py:109} ERROR - Failed to execute job 32 for task consume_task (type object 'KafkaException' has no attribute '_PARTITION_EOF'; 617)
[2023-12-24T00:51:13.585+0000] {local_task_job_runner.py:225} INFO - Task exited with return code 1
[2023-12-24T00:51:13.601+0000] {taskinstance.py:2653} INFO - 0 downstream tasks scheduled from follow-on schedule check
