[2024-02-05T06:46:52.539+0000] {taskinstance.py:1103} INFO - Dependencies all met for dep_context=non-requeueable deps ti=<TaskInstance: producer_dag.generate_random_data_task scheduled__2024-02-04T17:42:00+00:00 [queued]>
[2024-02-05T06:46:52.566+0000] {taskinstance.py:1103} INFO - Dependencies all met for dep_context=requeueable deps ti=<TaskInstance: producer_dag.generate_random_data_task scheduled__2024-02-04T17:42:00+00:00 [queued]>
[2024-02-05T06:46:52.567+0000] {taskinstance.py:1308} INFO - Starting attempt 1 of 1
[2024-02-05T06:46:52.603+0000] {taskinstance.py:1327} INFO - Executing <Task(PythonOperator): generate_random_data_task> on 2024-02-04 17:42:00+00:00
[2024-02-05T06:46:52.613+0000] {standard_task_runner.py:57} INFO - Started process 119 to run task
[2024-02-05T06:46:52.619+0000] {standard_task_runner.py:84} INFO - Running: ['***', 'tasks', 'run', 'producer_dag', 'generate_random_data_task', 'scheduled__2024-02-04T17:42:00+00:00', '--job-id', '1902', '--raw', '--subdir', 'DAGS_FOLDER/producer.py', '--cfg-path', '/tmp/tmp0y0493t9']
[2024-02-05T06:46:52.624+0000] {standard_task_runner.py:85} INFO - Job 1902: Subtask generate_random_data_task
[2024-02-05T06:46:52.727+0000] {task_command.py:410} INFO - Running <TaskInstance: producer_dag.generate_random_data_task scheduled__2024-02-04T17:42:00+00:00 [running]> on host 93456042b127
[2024-02-05T06:46:52.959+0000] {taskinstance.py:1547} INFO - Exporting env vars: AIRFLOW_CTX_DAG_OWNER='***' AIRFLOW_CTX_DAG_ID='producer_dag' AIRFLOW_CTX_TASK_ID='generate_random_data_task' AIRFLOW_CTX_EXECUTION_DATE='2024-02-04T17:42:00+00:00' AIRFLOW_CTX_TRY_NUMBER='1' AIRFLOW_CTX_DAG_RUN_ID='scheduled__2024-02-04T17:42:00+00:00'
[2024-02-05T06:47:14.172+0000] {taskinstance.py:1824} ERROR - Task failed with exception
Traceback (most recent call last):
  File "/home/airflow/.local/lib/python3.7/site-packages/airflow/operators/python.py", line 181, in execute
    return_value = self.execute_callable()
  File "/home/airflow/.local/lib/python3.7/site-packages/airflow/operators/python.py", line 198, in execute_callable
    return self.python_callable(*self.op_args, **self.op_kwargs)
  File "/opt/airflow/dags/producer.py", line 28, in generate_random_data
    password="airflow"
  File "/home/airflow/.local/lib/python3.7/site-packages/psycopg2/__init__.py", line 122, in connect
    conn = _connect(dsn, connection_factory=connection_factory, **kwasync)
psycopg2.OperationalError: connection to server at "192.168.35.95", port 5432 failed: Connection refused
	Is the server running on that host and accepting TCP/IP connections?

[2024-02-05T06:47:14.180+0000] {taskinstance.py:1350} INFO - Marking task as FAILED. dag_id=producer_dag, task_id=generate_random_data_task, execution_date=20240204T174200, start_date=20240205T064652, end_date=20240205T064714
[2024-02-05T06:47:14.195+0000] {standard_task_runner.py:109} ERROR - Failed to execute job 1902 for task generate_random_data_task (connection to server at "192.168.35.95", port 5432 failed: Connection refused
	Is the server running on that host and accepting TCP/IP connections?
; 119)
[2024-02-05T06:47:14.240+0000] {local_task_job_runner.py:225} INFO - Task exited with return code 1
[2024-02-05T06:47:14.261+0000] {taskinstance.py:2653} INFO - 0 downstream tasks scheduled from follow-on schedule check
