[2023-12-25T13:45:05.667+0000] {taskinstance.py:1103} INFO - Dependencies all met for dep_context=non-requeueable deps ti=<TaskInstance: consumer_dag.insert_task manual__2023-12-25T13:45:04.495771+00:00 [queued]>
[2023-12-25T13:45:05.675+0000] {taskinstance.py:1103} INFO - Dependencies all met for dep_context=requeueable deps ti=<TaskInstance: consumer_dag.insert_task manual__2023-12-25T13:45:04.495771+00:00 [queued]>
[2023-12-25T13:45:05.675+0000] {taskinstance.py:1308} INFO - Starting attempt 1 of 1
[2023-12-25T13:45:05.685+0000] {taskinstance.py:1327} INFO - Executing <Task(PythonOperator): insert_task> on 2023-12-25 13:45:04.495771+00:00
[2023-12-25T13:45:05.689+0000] {standard_task_runner.py:57} INFO - Started process 9285 to run task
[2023-12-25T13:45:05.691+0000] {standard_task_runner.py:84} INFO - Running: ['***', 'tasks', 'run', 'consumer_dag', 'insert_task', 'manual__2023-12-25T13:45:04.495771+00:00', '--job-id', '167', '--raw', '--subdir', 'DAGS_FOLDER/consumer.py', '--cfg-path', '/tmp/tmpd9do_3cg']
[2023-12-25T13:45:05.692+0000] {standard_task_runner.py:85} INFO - Job 167: Subtask insert_task
[2023-12-25T13:45:05.722+0000] {task_command.py:410} INFO - Running <TaskInstance: consumer_dag.insert_task manual__2023-12-25T13:45:04.495771+00:00 [running]> on host c56b1de7f6cf
[2023-12-25T13:45:05.779+0000] {taskinstance.py:1547} INFO - Exporting env vars: AIRFLOW_CTX_DAG_OWNER='***' AIRFLOW_CTX_DAG_ID='consumer_dag' AIRFLOW_CTX_TASK_ID='insert_task' AIRFLOW_CTX_EXECUTION_DATE='2023-12-25T13:45:04.495771+00:00' AIRFLOW_CTX_TRY_NUMBER='1' AIRFLOW_CTX_DAG_RUN_ID='manual__2023-12-25T13:45:04.495771+00:00'
[2023-12-25T13:45:05.788+0000] {taskinstance.py:1824} ERROR - Task failed with exception
Traceback (most recent call last):
  File "/home/airflow/.local/lib/python3.7/site-packages/airflow/operators/python.py", line 181, in execute
    return_value = self.execute_callable()
  File "/home/airflow/.local/lib/python3.7/site-packages/airflow/operators/python.py", line 198, in execute_callable
    return self.python_callable(*self.op_args, **self.op_kwargs)
  File "/opt/airflow/dags/consumer.py", line 46, in insert_to_db
    new_data = ti.xcom_pull(task_ids='consume')[0]
TypeError: 'NoneType' object is not subscriptable
[2023-12-25T13:45:05.793+0000] {taskinstance.py:1350} INFO - Marking task as FAILED. dag_id=consumer_dag, task_id=insert_task, execution_date=20231225T134504, start_date=20231225T134505, end_date=20231225T134505
[2023-12-25T13:45:05.801+0000] {standard_task_runner.py:109} ERROR - Failed to execute job 167 for task insert_task ('NoneType' object is not subscriptable; 9285)
[2023-12-25T13:45:05.823+0000] {local_task_job_runner.py:225} INFO - Task exited with return code 1
[2023-12-25T13:45:05.835+0000] {taskinstance.py:2653} INFO - 0 downstream tasks scheduled from follow-on schedule check
