[2024-01-09T05:52:00.897+0000] {taskinstance.py:1103} INFO - Dependencies all met for dep_context=non-requeueable deps ti=<TaskInstance: producer_dag.generate_random_data_task scheduled__2024-01-09T05:51:00+00:00 [queued]>
[2024-01-09T05:52:00.906+0000] {taskinstance.py:1103} INFO - Dependencies all met for dep_context=requeueable deps ti=<TaskInstance: producer_dag.generate_random_data_task scheduled__2024-01-09T05:51:00+00:00 [queued]>
[2024-01-09T05:52:00.906+0000] {taskinstance.py:1308} INFO - Starting attempt 1 of 1
[2024-01-09T05:52:00.917+0000] {taskinstance.py:1327} INFO - Executing <Task(PythonOperator): generate_random_data_task> on 2024-01-09 05:51:00+00:00
[2024-01-09T05:52:00.922+0000] {standard_task_runner.py:57} INFO - Started process 1887 to run task
[2024-01-09T05:52:00.924+0000] {standard_task_runner.py:84} INFO - Running: ['***', 'tasks', 'run', 'producer_dag', 'generate_random_data_task', 'scheduled__2024-01-09T05:51:00+00:00', '--job-id', '255', '--raw', '--subdir', 'DAGS_FOLDER/producer.py', '--cfg-path', '/tmp/tmpzz47mwr8']
[2024-01-09T05:52:00.926+0000] {standard_task_runner.py:85} INFO - Job 255: Subtask generate_random_data_task
[2024-01-09T05:52:00.960+0000] {task_command.py:410} INFO - Running <TaskInstance: producer_dag.generate_random_data_task scheduled__2024-01-09T05:51:00+00:00 [running]> on host 93456042b127
[2024-01-09T05:52:01.024+0000] {taskinstance.py:1547} INFO - Exporting env vars: AIRFLOW_CTX_DAG_OWNER='***' AIRFLOW_CTX_DAG_ID='producer_dag' AIRFLOW_CTX_TASK_ID='generate_random_data_task' AIRFLOW_CTX_EXECUTION_DATE='2024-01-09T05:51:00+00:00' AIRFLOW_CTX_TRY_NUMBER='1' AIRFLOW_CTX_DAG_RUN_ID='scheduled__2024-01-09T05:51:00+00:00'
[2024-01-09T05:52:22.082+0000] {taskinstance.py:1824} ERROR - Task failed with exception
Traceback (most recent call last):
  File "/home/airflow/.local/lib/python3.7/site-packages/airflow/operators/python.py", line 181, in execute
    return_value = self.execute_callable()
  File "/home/airflow/.local/lib/python3.7/site-packages/airflow/operators/python.py", line 198, in execute_callable
    return self.python_callable(*self.op_args, **self.op_kwargs)
  File "/opt/airflow/dags/producer.py", line 28, in generate_random_data
    password="airflow"
  File "/home/airflow/.local/lib/python3.7/site-packages/psycopg2/__init__.py", line 122, in connect
    conn = _connect(dsn, connection_factory=connection_factory, **kwasync)
psycopg2.OperationalError: connection to server at "192.168.35.140", port 5432 failed: Connection refused
	Is the server running on that host and accepting TCP/IP connections?

[2024-01-09T05:52:22.095+0000] {taskinstance.py:1350} INFO - Marking task as FAILED. dag_id=producer_dag, task_id=generate_random_data_task, execution_date=20240109T055100, start_date=20240109T055200, end_date=20240109T055222
[2024-01-09T05:52:22.109+0000] {standard_task_runner.py:109} ERROR - Failed to execute job 255 for task generate_random_data_task (connection to server at "192.168.35.140", port 5432 failed: Connection refused
	Is the server running on that host and accepting TCP/IP connections?
; 1887)
[2024-01-09T05:52:22.117+0000] {local_task_job_runner.py:225} INFO - Task exited with return code 1
[2024-01-09T05:52:22.136+0000] {taskinstance.py:2653} INFO - 0 downstream tasks scheduled from follow-on schedule check
