[2024-02-05T06:46:53.243+0000] {taskinstance.py:1103} INFO - Dependencies all met for dep_context=non-requeueable deps ti=<TaskInstance: retrain_dag.train_and_save_model scheduled__2024-02-04T17:42:00+00:00 [queued]>
[2024-02-05T06:46:53.257+0000] {taskinstance.py:1103} INFO - Dependencies all met for dep_context=requeueable deps ti=<TaskInstance: retrain_dag.train_and_save_model scheduled__2024-02-04T17:42:00+00:00 [queued]>
[2024-02-05T06:46:53.257+0000] {taskinstance.py:1308} INFO - Starting attempt 1 of 1
[2024-02-05T06:46:53.276+0000] {taskinstance.py:1327} INFO - Executing <Task(PythonOperator): train_and_save_model> on 2024-02-04 17:42:00+00:00
[2024-02-05T06:46:53.284+0000] {standard_task_runner.py:57} INFO - Started process 121 to run task
[2024-02-05T06:46:53.288+0000] {standard_task_runner.py:84} INFO - Running: ['***', 'tasks', 'run', 'retrain_dag', 'train_and_save_model', 'scheduled__2024-02-04T17:42:00+00:00', '--job-id', '1904', '--raw', '--subdir', 'DAGS_FOLDER/retrain_dag.py', '--cfg-path', '/tmp/tmpxojgtwow']
[2024-02-05T06:46:53.289+0000] {standard_task_runner.py:85} INFO - Job 1904: Subtask train_and_save_model
[2024-02-05T06:46:53.388+0000] {task_command.py:410} INFO - Running <TaskInstance: retrain_dag.train_and_save_model scheduled__2024-02-04T17:42:00+00:00 [running]> on host 93456042b127
[2024-02-05T06:46:53.559+0000] {taskinstance.py:1547} INFO - Exporting env vars: AIRFLOW_CTX_DAG_OWNER='***' AIRFLOW_CTX_DAG_ID='retrain_dag' AIRFLOW_CTX_TASK_ID='train_and_save_model' AIRFLOW_CTX_EXECUTION_DATE='2024-02-04T17:42:00+00:00' AIRFLOW_CTX_TRY_NUMBER='1' AIRFLOW_CTX_DAG_RUN_ID='scheduled__2024-02-04T17:42:00+00:00'
[2024-02-05T06:47:14.763+0000] {taskinstance.py:1824} ERROR - Task failed with exception
Traceback (most recent call last):
  File "/home/airflow/.local/lib/python3.7/site-packages/airflow/operators/python.py", line 181, in execute
    return_value = self.execute_callable()
  File "/home/airflow/.local/lib/python3.7/site-packages/airflow/operators/python.py", line 198, in execute_callable
    return self.python_callable(*self.op_args, **self.op_kwargs)
  File "/opt/airflow/dags/retrain_dag.py", line 25, in train_and_save_model
    password="airflow"
  File "/home/airflow/.local/lib/python3.7/site-packages/psycopg2/__init__.py", line 122, in connect
    conn = _connect(dsn, connection_factory=connection_factory, **kwasync)
psycopg2.OperationalError: connection to server at "192.168.35.95", port 5432 failed: Connection refused
	Is the server running on that host and accepting TCP/IP connections?

[2024-02-05T06:47:14.770+0000] {taskinstance.py:1350} INFO - Marking task as FAILED. dag_id=retrain_dag, task_id=train_and_save_model, execution_date=20240204T174200, start_date=20240205T064653, end_date=20240205T064714
[2024-02-05T06:47:14.780+0000] {standard_task_runner.py:109} ERROR - Failed to execute job 1904 for task train_and_save_model (connection to server at "192.168.35.95", port 5432 failed: Connection refused
	Is the server running on that host and accepting TCP/IP connections?
; 121)
[2024-02-05T06:47:14.822+0000] {local_task_job_runner.py:225} INFO - Task exited with return code 1
[2024-02-05T06:47:14.836+0000] {taskinstance.py:2653} INFO - 0 downstream tasks scheduled from follow-on schedule check
