[2023-10-20T14:12:29.848+0000] {taskinstance.py:1103} INFO - Dependencies all met for dep_context=non-requeueable deps ti=<TaskInstance: retrain_dag.train_and_save_model manual__2023-10-20T14:12:27.128648+00:00 [queued]>
[2023-10-20T14:12:29.853+0000] {taskinstance.py:1103} INFO - Dependencies all met for dep_context=requeueable deps ti=<TaskInstance: retrain_dag.train_and_save_model manual__2023-10-20T14:12:27.128648+00:00 [queued]>
[2023-10-20T14:12:29.853+0000] {taskinstance.py:1308} INFO - Starting attempt 1 of 1
[2023-10-20T14:12:29.864+0000] {taskinstance.py:1327} INFO - Executing <Task(PythonOperator): train_and_save_model> on 2023-10-20 14:12:27.128648+00:00
[2023-10-20T14:12:29.869+0000] {standard_task_runner.py:57} INFO - Started process 119 to run task
[2023-10-20T14:12:29.871+0000] {standard_task_runner.py:84} INFO - Running: ['***', 'tasks', 'run', 'retrain_dag', 'train_and_save_model', 'manual__2023-10-20T14:12:27.128648+00:00', '--job-id', '109', '--raw', '--subdir', 'DAGS_FOLDER/retrain_dag.py', '--cfg-path', '/tmp/tmpcuhjb23v']
[2023-10-20T14:12:29.872+0000] {standard_task_runner.py:85} INFO - Job 109: Subtask train_and_save_model
[2023-10-20T14:12:29.915+0000] {task_command.py:410} INFO - Running <TaskInstance: retrain_dag.train_and_save_model manual__2023-10-20T14:12:27.128648+00:00 [running]> on host bea49855d648
[2023-10-20T14:12:29.970+0000] {taskinstance.py:1547} INFO - Exporting env vars: AIRFLOW_CTX_DAG_OWNER='***' AIRFLOW_CTX_DAG_ID='retrain_dag' AIRFLOW_CTX_TASK_ID='train_and_save_model' AIRFLOW_CTX_EXECUTION_DATE='2023-10-20T14:12:27.128648+00:00' AIRFLOW_CTX_TRY_NUMBER='1' AIRFLOW_CTX_DAG_RUN_ID='manual__2023-10-20T14:12:27.128648+00:00'
[2023-10-20T14:12:51.195+0000] {taskinstance.py:1824} ERROR - Task failed with exception
Traceback (most recent call last):
  File "/home/airflow/.local/lib/python3.7/site-packages/airflow/operators/python.py", line 181, in execute
    return_value = self.execute_callable()
  File "/home/airflow/.local/lib/python3.7/site-packages/airflow/operators/python.py", line 198, in execute_callable
    return self.python_callable(*self.op_args, **self.op_kwargs)
  File "/opt/airflow/dags/retrain_dag.py", line 23, in train_and_save_model
    password="12345678"
  File "/home/airflow/.local/lib/python3.7/site-packages/psycopg2/__init__.py", line 122, in connect
    conn = _connect(dsn, connection_factory=connection_factory, **kwasync)
psycopg2.OperationalError: connection to server at "192.168.35.106", port 5432 failed: Connection refused
	Is the server running on that host and accepting TCP/IP connections?

[2023-10-20T14:12:51.348+0000] {taskinstance.py:1350} INFO - Marking task as FAILED. dag_id=retrain_dag, task_id=train_and_save_model, execution_date=20231020T141227, start_date=20231020T141229, end_date=20231020T141251
[2023-10-20T14:12:51.364+0000] {standard_task_runner.py:109} ERROR - Failed to execute job 109 for task train_and_save_model (connection to server at "192.168.35.106", port 5432 failed: Connection refused
	Is the server running on that host and accepting TCP/IP connections?
; 119)
[2023-10-20T14:12:51.377+0000] {local_task_job_runner.py:225} INFO - Task exited with return code 1
[2023-10-20T14:12:51.388+0000] {taskinstance.py:2653} INFO - 0 downstream tasks scheduled from follow-on schedule check
