[2023-10-20T14:12:29.848+0000] {taskinstance.py:1103} INFO - Dependencies all met for dep_context=non-requeueable deps ti=<TaskInstance: retrain_dag.train_and_save_model scheduled__2021-01-01T00:00:00+00:00 [queued]>
[2023-10-20T14:12:29.853+0000] {taskinstance.py:1103} INFO - Dependencies all met for dep_context=requeueable deps ti=<TaskInstance: retrain_dag.train_and_save_model scheduled__2021-01-01T00:00:00+00:00 [queued]>
[2023-10-20T14:12:29.853+0000] {taskinstance.py:1308} INFO - Starting attempt 1 of 1
[2023-10-20T14:12:29.862+0000] {taskinstance.py:1327} INFO - Executing <Task(PythonOperator): train_and_save_model> on 2021-01-01 00:00:00+00:00
[2023-10-20T14:12:29.867+0000] {standard_task_runner.py:57} INFO - Started process 118 to run task
[2023-10-20T14:12:29.870+0000] {standard_task_runner.py:84} INFO - Running: ['***', 'tasks', 'run', 'retrain_dag', 'train_and_save_model', 'scheduled__2021-01-01T00:00:00+00:00', '--job-id', '108', '--raw', '--subdir', 'DAGS_FOLDER/retrain_dag.py', '--cfg-path', '/tmp/tmp2ubs6jb8']
[2023-10-20T14:12:29.871+0000] {standard_task_runner.py:85} INFO - Job 108: Subtask train_and_save_model
[2023-10-20T14:12:29.904+0000] {task_command.py:410} INFO - Running <TaskInstance: retrain_dag.train_and_save_model scheduled__2021-01-01T00:00:00+00:00 [running]> on host bea49855d648
[2023-10-20T14:12:29.956+0000] {taskinstance.py:1547} INFO - Exporting env vars: AIRFLOW_CTX_DAG_OWNER='***' AIRFLOW_CTX_DAG_ID='retrain_dag' AIRFLOW_CTX_TASK_ID='train_and_save_model' AIRFLOW_CTX_EXECUTION_DATE='2021-01-01T00:00:00+00:00' AIRFLOW_CTX_TRY_NUMBER='1' AIRFLOW_CTX_DAG_RUN_ID='scheduled__2021-01-01T00:00:00+00:00'
[2023-10-20T14:12:51.195+0000] {taskinstance.py:1824} ERROR - Task failed with exception
Traceback (most recent call last):
  File "/home/airflow/.local/lib/python3.7/site-packages/airflow/operators/python.py", line 181, in execute
    return_value = self.execute_callable()
  File "/home/airflow/.local/lib/python3.7/site-packages/airflow/operators/python.py", line 198, in execute_callable
    return self.python_callable(*self.op_args, **self.op_kwargs)
  File "/opt/airflow/dags/retrain_dag.py", line 23, in train_and_save_model
    password="12345678"
  File "/home/airflow/.local/lib/python3.7/site-packages/psycopg2/__init__.py", line 122, in connect
    conn = _connect(dsn, connection_factory=connection_factory, **kwasync)
psycopg2.OperationalError: connection to server at "192.168.35.106", port 5432 failed: Connection refused
	Is the server running on that host and accepting TCP/IP connections?

[2023-10-20T14:12:51.348+0000] {taskinstance.py:1350} INFO - Marking task as FAILED. dag_id=retrain_dag, task_id=train_and_save_model, execution_date=20210101T000000, start_date=20231020T141229, end_date=20231020T141251
[2023-10-20T14:12:51.374+0000] {standard_task_runner.py:109} ERROR - Failed to execute job 108 for task train_and_save_model (connection to server at "192.168.35.106", port 5432 failed: Connection refused
	Is the server running on that host and accepting TCP/IP connections?
; 118)
[2023-10-20T14:12:51.383+0000] {local_task_job_runner.py:225} INFO - Task exited with return code 1
[2023-10-20T14:12:51.395+0000] {taskinstance.py:2653} INFO - 0 downstream tasks scheduled from follow-on schedule check
[2023-12-27T17:31:45.968+0000] {taskinstance.py:1103} INFO - Dependencies all met for dep_context=non-requeueable deps ti=<TaskInstance: retrain_dag.train_and_save_model scheduled__2021-01-01T00:00:00+00:00 [queued]>
[2023-12-27T17:31:45.976+0000] {taskinstance.py:1103} INFO - Dependencies all met for dep_context=requeueable deps ti=<TaskInstance: retrain_dag.train_and_save_model scheduled__2021-01-01T00:00:00+00:00 [queued]>
[2023-12-27T17:31:45.976+0000] {taskinstance.py:1308} INFO - Starting attempt 1 of 1
[2023-12-27T17:31:45.986+0000] {taskinstance.py:1327} INFO - Executing <Task(PythonOperator): train_and_save_model> on 2021-01-01 00:00:00+00:00
[2023-12-27T17:31:45.991+0000] {standard_task_runner.py:57} INFO - Started process 637 to run task
[2023-12-27T17:31:45.993+0000] {standard_task_runner.py:84} INFO - Running: ['***', 'tasks', 'run', 'retrain_dag', 'train_and_save_model', 'scheduled__2021-01-01T00:00:00+00:00', '--job-id', '529', '--raw', '--subdir', 'DAGS_FOLDER/retrain_dag.py', '--cfg-path', '/tmp/tmpwoe72wui']
[2023-12-27T17:31:45.993+0000] {standard_task_runner.py:85} INFO - Job 529: Subtask train_and_save_model
[2023-12-27T17:31:46.025+0000] {task_command.py:410} INFO - Running <TaskInstance: retrain_dag.train_and_save_model scheduled__2021-01-01T00:00:00+00:00 [running]> on host c56b1de7f6cf
[2023-12-27T17:31:46.080+0000] {taskinstance.py:1547} INFO - Exporting env vars: AIRFLOW_CTX_DAG_OWNER='***' AIRFLOW_CTX_DAG_ID='retrain_dag' AIRFLOW_CTX_TASK_ID='train_and_save_model' AIRFLOW_CTX_EXECUTION_DATE='2021-01-01T00:00:00+00:00' AIRFLOW_CTX_TRY_NUMBER='1' AIRFLOW_CTX_DAG_RUN_ID='scheduled__2021-01-01T00:00:00+00:00'
[2023-12-27T17:32:07.121+0000] {taskinstance.py:1824} ERROR - Task failed with exception
Traceback (most recent call last):
  File "/home/airflow/.local/lib/python3.7/site-packages/airflow/operators/python.py", line 181, in execute
    return_value = self.execute_callable()
  File "/home/airflow/.local/lib/python3.7/site-packages/airflow/operators/python.py", line 198, in execute_callable
    return self.python_callable(*self.op_args, **self.op_kwargs)
  File "/opt/airflow/dags/retrain_dag.py", line 25, in train_and_save_model
    password="airflow"
  File "/home/airflow/.local/lib/python3.7/site-packages/psycopg2/__init__.py", line 122, in connect
    conn = _connect(dsn, connection_factory=connection_factory, **kwasync)
psycopg2.OperationalError: connection to server at "192.168.35.133", port 5432 failed: Connection refused
	Is the server running on that host and accepting TCP/IP connections?

[2023-12-27T17:32:07.127+0000] {taskinstance.py:1350} INFO - Marking task as FAILED. dag_id=retrain_dag, task_id=train_and_save_model, execution_date=20210101T000000, start_date=20231227T173145, end_date=20231227T173207
[2023-12-27T17:32:07.135+0000] {standard_task_runner.py:109} ERROR - Failed to execute job 529 for task train_and_save_model (connection to server at "192.168.35.133", port 5432 failed: Connection refused
	Is the server running on that host and accepting TCP/IP connections?
; 637)
[2023-12-27T17:32:07.164+0000] {local_task_job_runner.py:225} INFO - Task exited with return code 1
[2023-12-27T17:32:07.175+0000] {taskinstance.py:2653} INFO - 0 downstream tasks scheduled from follow-on schedule check
