[2023-12-23T05:23:29.011+0000] {taskinstance.py:1103} INFO - Dependencies all met for dep_context=non-requeueable deps ti=<TaskInstance: producer_dag.generate_random_data_task manual__2023-12-23T05:23:28.066327+00:00 [queued]>
[2023-12-23T05:23:29.017+0000] {taskinstance.py:1103} INFO - Dependencies all met for dep_context=requeueable deps ti=<TaskInstance: producer_dag.generate_random_data_task manual__2023-12-23T05:23:28.066327+00:00 [queued]>
[2023-12-23T05:23:29.018+0000] {taskinstance.py:1308} INFO - Starting attempt 1 of 1
[2023-12-23T05:23:29.027+0000] {taskinstance.py:1327} INFO - Executing <Task(PythonOperator): generate_random_data_task> on 2023-12-23 05:23:28.066327+00:00
[2023-12-23T05:23:29.032+0000] {standard_task_runner.py:57} INFO - Started process 524 to run task
[2023-12-23T05:23:29.034+0000] {standard_task_runner.py:84} INFO - Running: ['***', 'tasks', 'run', 'producer_dag', 'generate_random_data_task', 'manual__2023-12-23T05:23:28.066327+00:00', '--job-id', '14', '--raw', '--subdir', 'DAGS_FOLDER/producer.py', '--cfg-path', '/tmp/tmp4ex_mb3w']
[2023-12-23T05:23:29.036+0000] {standard_task_runner.py:85} INFO - Job 14: Subtask generate_random_data_task
[2023-12-23T05:23:29.069+0000] {task_command.py:410} INFO - Running <TaskInstance: producer_dag.generate_random_data_task manual__2023-12-23T05:23:28.066327+00:00 [running]> on host 0a80305749dd
[2023-12-23T05:23:29.124+0000] {taskinstance.py:1547} INFO - Exporting env vars: AIRFLOW_CTX_DAG_OWNER='***' AIRFLOW_CTX_DAG_ID='producer_dag' AIRFLOW_CTX_TASK_ID='generate_random_data_task' AIRFLOW_CTX_EXECUTION_DATE='2023-12-23T05:23:28.066327+00:00' AIRFLOW_CTX_TRY_NUMBER='1' AIRFLOW_CTX_DAG_RUN_ID='manual__2023-12-23T05:23:28.066327+00:00'
[2023-12-23T05:23:29.133+0000] {taskinstance.py:1824} ERROR - Task failed with exception
Traceback (most recent call last):
  File "/home/airflow/.local/lib/python3.7/site-packages/pandas/io/sql.py", line 2056, in execute
    cur.execute(*args, **kwargs)
psycopg2.errors.UndefinedTable: relation "kwater" does not exist
LINE 1: SELECT * FROM kwater
                      ^


The above exception was the direct cause of the following exception:

Traceback (most recent call last):
  File "/home/airflow/.local/lib/python3.7/site-packages/airflow/operators/python.py", line 181, in execute
    return_value = self.execute_callable()
  File "/home/airflow/.local/lib/python3.7/site-packages/airflow/operators/python.py", line 198, in execute_callable
    return self.python_callable(*self.op_args, **self.op_kwargs)
  File "/opt/airflow/dags/producer.py", line 24, in generate_random_data
    df = pd.read_sql(query, conn)
  File "/home/airflow/.local/lib/python3.7/site-packages/pandas/io/sql.py", line 608, in read_sql
    chunksize=chunksize,
  File "/home/airflow/.local/lib/python3.7/site-packages/pandas/io/sql.py", line 2116, in read_query
    cursor = self.execute(*args)
  File "/home/airflow/.local/lib/python3.7/site-packages/pandas/io/sql.py", line 2068, in execute
    raise ex from exc
pandas.io.sql.DatabaseError: Execution failed on sql 'SELECT * FROM kwater': relation "kwater" does not exist
LINE 1: SELECT * FROM kwater
                      ^

[2023-12-23T05:23:29.140+0000] {taskinstance.py:1350} INFO - Marking task as FAILED. dag_id=producer_dag, task_id=generate_random_data_task, execution_date=20231223T052328, start_date=20231223T052329, end_date=20231223T052329
[2023-12-23T05:23:29.147+0000] {standard_task_runner.py:109} ERROR - Failed to execute job 14 for task generate_random_data_task (Execution failed on sql 'SELECT * FROM kwater': relation "kwater" does not exist
LINE 1: SELECT * FROM kwater
                      ^
; 524)
[2023-12-23T05:23:29.166+0000] {local_task_job_runner.py:225} INFO - Task exited with return code 1
[2023-12-23T05:23:29.183+0000] {taskinstance.py:2653} INFO - 0 downstream tasks scheduled from follow-on schedule check
