[2024-01-03T11:36:06.224+0000] {taskinstance.py:1103} INFO - Dependencies all met for dep_context=non-requeueable deps ti=<TaskInstance: producer_dag.generate_random_data_task scheduled__2024-01-03T11:34:00+00:00 [queued]>
[2024-01-03T11:36:06.230+0000] {taskinstance.py:1103} INFO - Dependencies all met for dep_context=requeueable deps ti=<TaskInstance: producer_dag.generate_random_data_task scheduled__2024-01-03T11:34:00+00:00 [queued]>
[2024-01-03T11:36:06.230+0000] {taskinstance.py:1308} INFO - Starting attempt 1 of 1
[2024-01-03T11:36:06.240+0000] {taskinstance.py:1327} INFO - Executing <Task(PythonOperator): generate_random_data_task> on 2024-01-03 11:34:00+00:00
[2024-01-03T11:36:06.244+0000] {standard_task_runner.py:57} INFO - Started process 155 to run task
[2024-01-03T11:36:06.247+0000] {standard_task_runner.py:84} INFO - Running: ['***', 'tasks', 'run', 'producer_dag', 'generate_random_data_task', 'scheduled__2024-01-03T11:34:00+00:00', '--job-id', '5', '--raw', '--subdir', 'DAGS_FOLDER/producer.py', '--cfg-path', '/tmp/tmpu8fpf9jt']
[2024-01-03T11:36:06.249+0000] {standard_task_runner.py:85} INFO - Job 5: Subtask generate_random_data_task
[2024-01-03T11:36:06.285+0000] {task_command.py:410} INFO - Running <TaskInstance: producer_dag.generate_random_data_task scheduled__2024-01-03T11:34:00+00:00 [running]> on host 93456042b127
[2024-01-03T11:36:06.338+0000] {taskinstance.py:1547} INFO - Exporting env vars: AIRFLOW_CTX_DAG_OWNER='***' AIRFLOW_CTX_DAG_ID='producer_dag' AIRFLOW_CTX_TASK_ID='generate_random_data_task' AIRFLOW_CTX_EXECUTION_DATE='2024-01-03T11:34:00+00:00' AIRFLOW_CTX_TRY_NUMBER='1' AIRFLOW_CTX_DAG_RUN_ID='scheduled__2024-01-03T11:34:00+00:00'
[2024-01-03T11:36:06.347+0000] {taskinstance.py:1824} ERROR - Task failed with exception
Traceback (most recent call last):
  File "/home/airflow/.local/lib/python3.7/site-packages/pandas/io/sql.py", line 2056, in execute
    cur.execute(*args, **kwargs)
psycopg2.errors.UndefinedTable: relation "kwater" does not exist
LINE 1: SELECT * FROM kwater
                      ^


The above exception was the direct cause of the following exception:

Traceback (most recent call last):
  File "/home/airflow/.local/lib/python3.7/site-packages/airflow/operators/python.py", line 181, in execute
    return_value = self.execute_callable()
  File "/home/airflow/.local/lib/python3.7/site-packages/airflow/operators/python.py", line 198, in execute_callable
    return self.python_callable(*self.op_args, **self.op_kwargs)
  File "/opt/airflow/dags/producer.py", line 31, in generate_random_data
    df = pd.read_sql(query, conn)
  File "/home/airflow/.local/lib/python3.7/site-packages/pandas/io/sql.py", line 608, in read_sql
    chunksize=chunksize,
  File "/home/airflow/.local/lib/python3.7/site-packages/pandas/io/sql.py", line 2116, in read_query
    cursor = self.execute(*args)
  File "/home/airflow/.local/lib/python3.7/site-packages/pandas/io/sql.py", line 2068, in execute
    raise ex from exc
pandas.io.sql.DatabaseError: Execution failed on sql 'SELECT * FROM kwater': relation "kwater" does not exist
LINE 1: SELECT * FROM kwater
                      ^

[2024-01-03T11:36:06.352+0000] {taskinstance.py:1350} INFO - Marking task as FAILED. dag_id=producer_dag, task_id=generate_random_data_task, execution_date=20240103T113400, start_date=20240103T113606, end_date=20240103T113606
[2024-01-03T11:36:06.365+0000] {standard_task_runner.py:109} ERROR - Failed to execute job 5 for task generate_random_data_task (Execution failed on sql 'SELECT * FROM kwater': relation "kwater" does not exist
LINE 1: SELECT * FROM kwater
                      ^
; 155)
[2024-01-03T11:36:06.379+0000] {local_task_job_runner.py:225} INFO - Task exited with return code 1
[2024-01-03T11:36:06.396+0000] {taskinstance.py:2653} INFO - 0 downstream tasks scheduled from follow-on schedule check
