[2023-12-25T09:45:33.708+0000] {taskinstance.py:1103} INFO - Dependencies all met for dep_context=non-requeueable deps ti=<TaskInstance: producer_dag.check_kafka_topic_task manual__2023-12-25T09:45:19.982029+00:00 [queued]>
[2023-12-25T09:45:33.735+0000] {taskinstance.py:1103} INFO - Dependencies all met for dep_context=requeueable deps ti=<TaskInstance: producer_dag.check_kafka_topic_task manual__2023-12-25T09:45:19.982029+00:00 [queued]>
[2023-12-25T09:45:33.735+0000] {taskinstance.py:1308} INFO - Starting attempt 1 of 1
[2023-12-25T09:45:33.784+0000] {taskinstance.py:1327} INFO - Executing <Task(PythonOperator): check_kafka_topic_task> on 2023-12-25 09:45:19.982029+00:00
[2023-12-25T09:45:33.797+0000] {standard_task_runner.py:57} INFO - Started process 1074 to run task
[2023-12-25T09:45:33.807+0000] {standard_task_runner.py:84} INFO - Running: ['***', 'tasks', 'run', 'producer_dag', 'check_kafka_topic_task', 'manual__2023-12-25T09:45:19.982029+00:00', '--job-id', '30', '--raw', '--subdir', 'DAGS_FOLDER/producer.py', '--cfg-path', '/tmp/tmph1lief5r']
[2023-12-25T09:45:33.815+0000] {standard_task_runner.py:85} INFO - Job 30: Subtask check_kafka_topic_task
[2023-12-25T09:45:34.028+0000] {task_command.py:410} INFO - Running <TaskInstance: producer_dag.check_kafka_topic_task manual__2023-12-25T09:45:19.982029+00:00 [running]> on host 0fa599bd5d59
[2023-12-25T09:45:34.407+0000] {taskinstance.py:1547} INFO - Exporting env vars: AIRFLOW_CTX_DAG_OWNER='***' AIRFLOW_CTX_DAG_ID='producer_dag' AIRFLOW_CTX_TASK_ID='check_kafka_topic_task' AIRFLOW_CTX_EXECUTION_DATE='2023-12-25T09:45:19.982029+00:00' AIRFLOW_CTX_TRY_NUMBER='1' AIRFLOW_CTX_DAG_RUN_ID='manual__2023-12-25T09:45:19.982029+00:00'
[2023-12-25T09:45:34.408+0000] {taskinstance.py:1824} ERROR - Task failed with exception
Traceback (most recent call last):
  File "/home/airflow/.local/lib/python3.7/site-packages/airflow/operators/python.py", line 181, in execute
    return_value = self.execute_callable()
  File "/home/airflow/.local/lib/python3.7/site-packages/airflow/operators/python.py", line 198, in execute_callable
    return self.python_callable(*self.op_args, **self.op_kwargs)
TypeError: check_and_print_kafka_topic_exists() missing 1 required positional argument: 'kafka_topic'
[2023-12-25T09:45:34.448+0000] {taskinstance.py:1350} INFO - Marking task as FAILED. dag_id=producer_dag, task_id=check_kafka_topic_task, execution_date=20231225T094519, start_date=20231225T094533, end_date=20231225T094534
[2023-12-25T09:45:34.496+0000] {standard_task_runner.py:109} ERROR - Failed to execute job 30 for task check_kafka_topic_task (check_and_print_kafka_topic_exists() missing 1 required positional argument: 'kafka_topic'; 1074)
[2023-12-25T09:45:34.517+0000] {local_task_job_runner.py:225} INFO - Task exited with return code 1
[2023-12-25T09:45:34.585+0000] {taskinstance.py:2653} INFO - 0 downstream tasks scheduled from follow-on schedule check
